Workbook

Sheet 商品类型
A1: 名称 | B1: 基础价格
A2: 硅 | B2: 25
A3: 芯片 | B3: 75
A4: 手机 | B4: 700
A5: 棉花 | B5: 42
A6: 布料 | B6: 140
A7: 服装 | B7: 330
A8: 小麦 | B8: 10
A9: 面粉 | B9: 70
A10: 食品 | B10: 120

Sheet 配方
A1: 名称 | B1: 输入商品 | C1: 输入数量 | D1: 输出商品 | E1: 输出数量 | F1: 科技品质权重
A2: 硅矿开采 | B2: (无) | C2: 0 | D2: 硅 | E2: 4000 | F2: 1
A3: 芯片制造 | B3: 硅 | C3: 2000 | D3: 芯片 | E3: 1200 | F3: 0.6
A4: 手机组装 | B4: 芯片 | C4: 600 | D4: 手机 | E4: 125 | F4: 0.5
A5: 棉花种植 | B5: (无) | C5: 0 | D5: 棉花 | E5: 700 | F5: 1
A6: 布料加工 | B6: 棉花 | C6: 500 | D6: 布料 | E6: 340 | F6: 0.6
A7: 服装生产 | B7: 布料 | C7: 300 | D7: 服装 | E7: 200 | F7: 0.5
A8: 小麦种植 | B8: (无) | C8: 0 | D8: 小麦 | E8: 3000 | F8: 1
A9: 面粉加工 | B9: 小麦 | C9: 2000 | D9: 面粉 | E9: 1000 | F9: 0.6
A10: 食品生产 | B10: 面粉 | C10: 1000 | D10: 食品 | E10: 800 | F10: 0.5

Sheet 工厂类型
A1: 名称 | B1: 配方 | C1: 劳动力需求 | D1: 建造成本 | E1: 维护费 | F1: 建造时间
A2: 硅矿场 | B2: 硅矿开采 | C2: 200 | D2: 80000 | E2: 10000 | F2: 2
A3: 芯片工厂 | B3: 芯片制造 | C3: 60 | D3: 50000 | E3: 7000 | F3: 2
A4: 手机工厂 | B4: 手机组装 | C4: 40 | D4: 70000 | E4: 8000 | F4: 2
A5: 棉花农场 | B5: 棉花种植 | C5: 60 | D5: 30000 | E5: 2000 | F5: 2
A6: 纺织厂 | B6: 布料加工 | C6: 40 | D6: 60000 | E6: 3000 | F6: 2
A7: 服装厂 | B7: 服装生产 | C7: 40 | D7: 50000 | E7: 2000 | F7: 2
A8: 麦田 | B8: 小麦种植 | C8: 60 | D8: 40000 | E8: 1000 | F8: 2
A9: 面粉厂 | B9: 面粉加工 | C9: 100 | D9: 40000 | E9: 2500 | F9: 2
A10: 食品厂 | B10: 食品生产 | C10: 40 | D10: 45000 | E10: 2800 | F10: 2

Sheet 居民配置
A1: 群体名称 | B1: 人口 | C1: 品质权重 | D1: 品牌权重 | E1: 价格权重 | F1: 劳动参与率 | G1: 人均劳动力 | H1: 食品-人均需求 | I1: 食品-敏感度 | J1: 服装-人均需求 | K1: 服装-敏感度 | L1: 手机-人均需求 | M1: 手机-敏感度
A2: 低收入群体 | B2: 6000 | C2: 0.4 | D2: 0.05 | E2: 0.55 | F2: 0.7 | G2: 1 | H2: 1 | I2: 0.1 | J2: 0.2 | K2: 0.5 | L2: 0.1 | M2: 0.8
A3: 中等收入群体 | B3: 3000 | C3: 0.35 | D3: 0.35 | E3: 0.3 | F3: 0.6 | G3: 1 | H3: 1.2 | I3: 0.2 | J3: 0.5 | K3: 0.5 | L3: 0.4 | M3: 0.7
A4: 高收入群体 | B4: 1000 | C4: 0.15 | D4: 0.75 | E4: 0.1 | F4: 0.4 | G4: 1 | H4: 1.5 | I4: 0.05 | J4: 0.7 | K4: 0.3 | L4: 0.7 | M4: 0.4
B5: =SUM(B2:B4) -> 10000

Sheet 经济分析
A1: 统一工资 | B1: 400
A3: 工厂名称 | B3: 产业链 | C3: 产出商品 | D3: 产出数量 | E3: 商品售价 | F3: 收入 | G3: 劳动力需求 | H3: 工资支出 | I3: 维护费 | J3: 输入商品 | K3: 输入数量 | L3: 原料单价 | M3: 原料成本 | N3: 总成本 | O3: 利润 | P3: 利润率 | Q3: 建造成本 | R3: 单回合ROI | S3: 回本回合数
A4: 硅矿场 | B4: 电子 | C4: 硅 | D4: =配方!E2 -> 4000 | E4: =商品类型!B2 -> 25 | F4: =D4*E4 -> 100000 | G4: =工厂类型!C2 -> 200 | H4: =G4*$B$1 -> 80000 | I4: =工厂类型!E2 -> 10000 | J4: (无) | K4: =配方!C2 -> 0 | L4: 0 | M4: =K4*L4 -> 0 | N4: =H4+I4+M4 -> 90000 | O4: =F4-N4 -> 10000 | P4: =IF(F4=0,0,O4/F4) -> 0.1 | Q4: =工厂类型!D2 -> 80000 | R4: =IF(Q4=0,0,O4/Q4) -> 0.125 | S4: =IF(O4<=0,"亏损",Q4/O4) -> 8
A5: 芯片工厂 | B5: 电子 | C5: 芯片 | D5: =配方!E3 -> 1200 | E5: =商品类型!B3 -> 75 | F5: =D5*E5 -> 90000 | G5: =工厂类型!C3 -> 60 | H5: =G5*$B$1 -> 24000 | I5: =工厂类型!E3 -> 7000 | J5: 硅 | K5: =配方!C3 -> 2000 | L5: =商品类型!B2 -> 25 | M5: =K5*L5 -> 50000 | N5: =H5+I5+M5 -> 81000 | O5: =F5-N5 -> 9000 | P5: =IF(F5=0,0,O5/F5) -> 0.1 | Q5: =工厂类型!D3 -> 50000 | R5: =IF(Q5=0,0,O5/Q5) -> 0.18 | S5: =IF(O5<=0,"亏损",Q5/O5) -> 5.5555556
A6: 手机工厂 | B6: 电子 | C6: 手机 | D6: =配方!E4 -> 125 | E6: =商品类型!B4 -> 700 | F6: =D6*E6 -> 87500 | G6: =工厂类型!C4 -> 40 | H6: =G6*$B$1 -> 16000 | I6: =工厂类型!E4 -> 8000 | J6: 芯片 | K6: =配方!C4 -> 600 | L6: =商品类型!B3 -> 75 | M6: =K6*L6 -> 45000 | N6: =H6+I6+M6 -> 69000 | O6: =F6-N6 -> 18500 | P6: =IF(F6=0,0,O6/F6) -> 0.21142857 | Q6: =工厂类型!D4 -> 70000 | R6: =IF(Q6=0,0,O6/Q6) -> 0.26428571 | S6: =IF(O6<=0,"亏损",Q6/O6) -> 3.7837838
A7: 棉花农场 | B7: 纺织 | C7: 棉花 | D7: =配方!E5 -> 700 | E7: =商品类型!B5 -> 42 | F7: =D7*E7 -> 29400 | G7: =工厂类型!C5 -> 60 | H7: =G7*$B$1 -> 24000 | I7: =工厂类型!E5 -> 2000 | J7: (无) | K7: =配方!C5 -> 0 | L7: 0 | M7: =K7*L7 -> 0 | N7: =H7+I7+M7 -> 26000 | O7: =F7-N7 -> 3400 | P7: =IF(F7=0,0,O7/F7) -> 0.11564626 | Q7: =工厂类型!D5 -> 30000 | R7: =IF(Q7=0,0,O7/Q7) -> 0.11333333 | S7: =IF(O7<=0,"亏损",Q7/O7) -> 8.8235294
A8: 纺织厂 | B8: 纺织 | C8: 布料 | D8: =配方!E6 -> 340 | E8: =商品类型!B6 -> 140 | F8: =D8*E8 -> 47600 | G8: =工厂类型!C6 -> 40 | H8: =G8*$B$1 -> 16000 | I8: =工厂类型!E6 -> 3000 | J8: 棉花 | K8: =配方!C6 -> 500 | L8: =商品类型!B5 -> 42 | M8: =K8*L8 -> 21000 | N8: =H8+I8+M8 -> 40000 | O8: =F8-N8 -> 7600 | P8: =IF(F8=0,0,O8/F8) -> 0.15966387 | Q8: =工厂类型!D6 -> 60000 | R8: =IF(Q8=0,0,O8/Q8) -> 0.12666667 | S8: =IF(O8<=0,"亏损",Q8/O8) -> 7.8947368
A9: 服装厂 | B9: 纺织 | C9: 服装 | D9: =配方!E7 -> 200 | E9: =商品类型!B7 -> 330 | F9: =D9*E9 -> 66000 | G9: =工厂类型!C7 -> 40 | H9: =G9*$B$1 -> 16000 | I9: =工厂类型!E7 -> 2000 | J9: 布料 | K9: =配方!C7 -> 300 | L9: =商品类型!B6 -> 140 | M9: =K9*L9 -> 42000 | N9: =H9+I9+M9 -> 60000 | O9: =F9-N9 -> 6000 | P9: =IF(F9=0,0,O9/F9) -> 0.090909091 | Q9: =工厂类型!D7 -> 50000 | R9: =IF(Q9=0,0,O9/Q9) -> 0.12 | S9: =IF(O9<=0,"亏损",Q9/O9) -> 8.3333333
A10: 麦田 | B10: 食品 | C10: 小麦 | D10: =配方!E8 -> 3000 | E10: =商品类型!B8 -> 10 | F10: =D10*E10 -> 30000 | G10: =工厂类型!C8 -> 60 | H10: =G10*$B$1 -> 24000 | I10: =工厂类型!E8 -> 1000 | J10: (无) | K10: =配方!C8 -> 0 | L10: 0 | M10: =K10*L10 -> 0 | N10: =H10+I10+M10 -> 25000 | O10: =F10-N10 -> 5000 | P10: =IF(F10=0,0,O10/F10) -> 0.16666667 | Q10: =工厂类型!D8 -> 40000 | R10: =IF(Q10=0,0,O10/Q10) -> 0.125 | S10: =IF(O10<=0,"亏损",Q10/O10) -> 8
A11: 面粉厂 | B11: 食品 | C11: 面粉 | D11: =配方!E9 -> 1000 | E11: =商品类型!B9 -> 70 | F11: =D11*E11 -> 70000 | G11: =工厂类型!C9 -> 100 | H11: =G11*$B$1 -> 40000 | I11: =工厂类型!E9 -> 2500 | J11: 小麦 | K11: =配方!C9 -> 2000 | L11: =商品类型!B8 -> 10 | M11: =K11*L11 -> 20000 | N11: =H11+I11+M11 -> 62500 | O11: =F11-N11 -> 7500 | P11: =IF(F11=0,0,O11/F11) -> 0.10714286 | Q11: =工厂类型!D9 -> 40000 | R11: =IF(Q11=0,0,O11/Q11) -> 0.1875 | S11: =IF(O11<=0,"亏损",Q11/O11) -> 5.3333333
A12: 食品厂 | B12: 食品 | C12: 食品 | D12: =配方!E10 -> 800 | E12: =商品类型!B10 -> 120 | F12: =D12*E12 -> 96000 | G12: =工厂类型!C10 -> 40 | H12: =G12*$B$1 -> 16000 | I12: =工厂类型!E10 -> 2800 | J12: 面粉 | K12: =配方!C10 -> 1000 | L12: =商品类型!B9 -> 70 | M12: =K12*L12 -> 70000 | N12: =H12+I12+M12 -> 88800 | O12: =F12-N12 -> 7200 | P12: =IF(F12=0,0,O12/F12) -> 0.075 | Q12: =工厂类型!D10 -> 45000 | R12: =IF(Q12=0,0,O12/Q12) -> 0.16 | S12: =IF(O12<=0,"亏损",Q12/O12) -> 6.25

Sheet 需求分析
A1: 经济周期参数
A2: 短周期振幅 A1 | B2: 0.45
A3: 长周期振幅 A2 | B3: 0.25
A4: 理论最高指数 | B4: 0.7
A5: 理论最低指数 | B5: -0.7
A7: 经济指数 = 0 (基准)
A8: 商品 | B8: 群体 | C8: 人口 | D8: 人均需求 | E8: 敏感度 | F8: 需求量
A9: 食品 | B9: 低收入群体 | C9: =居民配置!B2 -> 6000 | D9: =居民配置!H2 -> 1 | E9: =居民配置!I2 -> 0.1 | F9: =INT(C9*D9*(1+0*E9)) -> 6000
B10: 中等收入群体 | C10: =居民配置!B3 -> 3000 | D10: =居民配置!H3 -> 1.2 | E10: =居民配置!I3 -> 0.2 | F10: =INT(C10*D10*(1+0*E10)) -> 3600
B11: 高收入群体 | C11: =居民配置!B4 -> 1000 | D11: =居民配置!H4 -> 1.5 | E11: =居民配置!I4 -> 0.05 | F11: =INT(C11*D11*(1+0*E11)) -> 1500
B12: 食品 合计 | F12: =F9+F10+F11 -> 11100
A13: 服装 | B13: 低收入群体 | C13: =居民配置!B2 -> 6000 | D13: =居民配置!J2 -> 0.2 | E13: =居民配置!K2 -> 0.5 | F13: =INT(C13*D13*(1+0*E13)) -> 1200
B14: 中等收入群体 | C14: =居民配置!B3 -> 3000 | D14: =居民配置!J3 -> 0.5 | E14: =居民配置!K3 -> 0.5 | F14: =INT(C14*D14*(1+0*E14)) -> 1500
B15: 高收入群体 | C15: =居民配置!B4 -> 1000 | D15: =居民配置!J4 -> 0.7 | E15: =居民配置!K4 -> 0.3 | F15: =INT(C15*D15*(1+0*E15)) -> 700
B16: 服装 合计 | F16: =F13+F14+F15 -> 3400
A17: 手机 | B17: 低收入群体 | C17: =居民配置!B2 -> 6000 | D17: =居民配置!L2 -> 0.1 | E17: =居民配置!M2 -> 0.8 | F17: =INT(C17*D17*(1+0*E17)) -> 600
B18: 中等收入群体 | C18: =居民配置!B3 -> 3000 | D18: =居民配置!L3 -> 0.4 | E18: =居民配置!M3 -> 0.7 | F18: =INT(C18*D18*(1+0*E18)) -> 1200
B19: 高收入群体 | C19: =居民配置!B4 -> 1000 | D19: =居民配置!L4 -> 0.7 | E19: =居民配置!M4 -> 0.4 | F19: =INT(C19*D19*(1+0*E19)) -> 700
B20: 手机 合计 | F20: =F17+F18+F19 -> 2500
A22: 所需工厂数量 (经济指数 = 0 (基准))
A23: 产业链 | B23: 层级 | C23: 工厂类型 | D23: 单厂产出 | E23: 终端需求 | F23: 原料需求系数 | G23: 所需产量 | H23: 所需工厂数(向上取整)
A24: 电子 | B24: 终端 | C24: 手机工厂 | D24: =配方!E4 -> 125 | E24: =F20 -> 2500 | F24: 1 | G24: =E24 -> 2500 | H24: =ROUNDUP(G24/D24,0) -> 20
B25: 中间 | C25: 芯片工厂 | D25: =配方!E3 -> 1200 | E25: =E24 -> 2500 | F25: =配方!C4/配方!E4 -> 4.8 | G25: =ROUNDUP(E25*F25,0) -> 12000 | H25: =ROUNDUP(G25/D25,0) -> 10
B26: 原料 | C26: 硅矿场 | D26: =配方!E2 -> 4000 | E26: =E24 -> 2500 | F26: =(配方!C4/配方!E4)*(配方!C3/配方!E3) -> 8 | G26: =ROUNDUP(E26*F26,0) -> 20000 | H26: =ROUNDUP(G26/D26,0) -> 5
A27: 纺织 | B27: 终端 | C27: 服装厂 | D27: =配方!E7 -> 200 | E27: =F16 -> 3400 | F27: 1 | G27: =E27 -> 3400 | H27: =ROUNDUP(G27/D27,0) -> 17
B28: 中间 | C28: 纺织厂 | D28: =配方!E6 -> 340 | E28: =E27 -> 3400 | F28: =配方!C7/配方!E7 -> 1.5 | G28: =ROUNDUP(E28*F28,0) -> 5100 | H28: =ROUNDUP(G28/D28,0) -> 15
B29: 原料 | C29: 棉花农场 | D29: =配方!E5 -> 700 | E29: =E27 -> 3400 | F29: =(配方!C7/配方!E7)*(配方!C6/配方!E6) -> 2.2058824 | G29: =ROUNDUP(E29*F29,0) -> 7500 | H29: =ROUNDUP(G29/D29,0) -> 11
A30: 食品 | B30: 终端 | C30: 食品厂 | D30: =配方!E10 -> 800 | E30: =F12 -> 11100 | F30: 1 | G30: =E30 -> 11100 | H30: =ROUNDUP(G30/D30,0) -> 14
B31: 中间 | C31: 面粉厂 | D31: =配方!E9 -> 1000 | E31: =E30 -> 11100 | F31: =配方!C10/配方!E10 -> 1.25 | G31: =ROUNDUP(E31*F31,0) -> 13875 | H31: =ROUNDUP(G31/D31,0) -> 14
B32: 原料 | C32: 麦田 | D32: =配方!E8 -> 3000 | E32: =E30 -> 11100 | F32: =(配方!C10/配方!E10)*(配方!C9/配方!E9) -> 2.5 | G32: =ROUNDUP(E32*F32,0) -> 27750 | H32: =ROUNDUP(G32/D32,0) -> 10
H33: =SUM(H24:H32) -> 116
A34: 经济指数 = 0.7 (繁荣顶峰)
A35: 商品 | B35: 群体 | C35: 人口 | D35: 人均需求 | E35: 敏感度 | F35: 需求量
A36: 食品 | B36: 低收入群体 | C36: =居民配置!B2 -> 6000 | D36: =居民配置!H2 -> 1 | E36: =居民配置!I2 -> 0.1 | F36: =INT(C36*D36*(1+0.7*E36)) -> 6420
B37: 中等收入群体 | C37: =居民配置!B3 -> 3000 | D37: =居民配置!H3 -> 1.2 | E37: =居民配置!I3 -> 0.2 | F37: =INT(C37*D37*(1+0.7*E37)) -> 4104
B38: 高收入群体 | C38: =居民配置!B4 -> 1000 | D38: =居民配置!H4 -> 1.5 | E38: =居民配置!I4 -> 0.05 | F38: =INT(C38*D38*(1+0.7*E38)) -> 1552
B39: 食品 合计 | F39: =F36+F37+F38 -> 12076
A40: 服装 | B40: 低收入群体 | C40: =居民配置!B2 -> 6000 | D40: =居民配置!J2 -> 0.2 | E40: =居民配置!K2 -> 0.5 | F40: =INT(C40*D40*(1+0.7*E40)) -> 1620
B41: 中等收入群体 | C41: =居民配置!B3 -> 3000 | D41: =居民配置!J3 -> 0.5 | E41: =居民配置!K3 -> 0.5 | F41: =INT(C41*D41*(1+0.7*E41)) -> 2025
B42: 高收入群体 | C42: =居民配置!B4 -> 1000 | D42: =居民配置!J4 -> 0.7 | E42: =居民配置!K4 -> 0.3 | F42: =INT(C42*D42*(1+0.7*E42)) -> 847
...

Sheet 现金总量分析
A1: 各部门初始现金明细
A2: 类别 | B2: 名称 | C2: 数量 | D2: 单位现金 | E2: 小计
A3: 企业 | B3: 硅矿场 | C3: 2 | D3: 100000 | E3: =C3*D3 -> 200000
A4: 企业 | B4: 芯片工厂 | C4: 2 | D4: 200000 | E4: =C4*D4 -> 400000
A5: 企业 | B5: 手机工厂 | C5: 2 | D5: 150000 | E5: =C5*D5 -> 300000
A6: 企业 | B6: 棉花农场 | C6: 2 | D6: 80000 | E6: =C6*D6 -> 160000
A7: 企业 | B7: 纺织厂 | C7: 2 | D7: 120000 | E7: =C7*D7 -> 240000
A8: 企业 | B8: 服装厂 | C8: 2 | D8: 100000 | E8: =C8*D8 -> 200000
A9: 企业 | B9: 麦田 | C9: 3 | D9: 60000 | E9: =C9*D9 -> 180000
A10: 企业 | B10: 面粉厂 | C10: 2 | D10: 80000 | E10: =C10*D10 -> 160000
A11: 企业 | B11: 食品厂 | C11: 2 | D11: 90000 | E11: =C11*D11 -> 180000
B12: 企业合计 | E12: =SUM(E3:E11) -> 2020000
A13: 银行 | B13: 银行A | C13: 1 | D13: 2000000 | E13: =C13*D13 -> 2000000
A14: 银行 | B14: 银行B | C14: 1 | D14: 2000000 | E14: =C14*D14 -> 2000000
B15: 银行合计 | E15: =SUM(E13:E14) -> 4000000
A16: 居民 | B16: 全体居民(3群体) | C16: 3 | D16: 500000 | E16: =C16*D16 -> 1500000
B18: 系统现金总量 | E18: =E12+E15+E16 -> 7520000
A20: 现金分布占比
A21: 部门 | B21: 现金 | C21: 占比
A22: 企业 | B22: =E12 -> 2020000 | C22: =E12/E18 -> 0.26861702
A23: 银行 | B23: =E15 -> 4000000 | C23: =E15/E18 -> 0.53191489
A24: 居民 | B24: =E16 -> 1500000 | C24: =E16/E18 -> 0.19946809
A26: 现金总量 / 工厂建造成本
A27: 工厂类型 | B27: 建造成本 | C27: 现金总量 | D27: 可建造数量 | E27: 备注
A28: 硅矿场 | B28: =工厂类型!D2 -> 80000 | C28: =E18 -> 7520000 | D28: =INT(C28/B28) -> 94 | E28: =IF(D28<20,"偏贵",IF(D28>200,"偏便宜","合理")) -> 合理
A29: 芯片工厂 | B29: =工厂类型!D3 -> 50000 | C29: =E18 -> 7520000 | D29: =INT(C29/B29) -> 150 | E29: =IF(D29<20,"偏贵",IF(D29>200,"偏便宜","合理")) -> 合理
A30: 手机工厂 | B30: =工厂类型!D4 -> 70000 | C30: =E18 -> 7520000 | D30: =INT(C30/B30) -> 107 | E30: =IF(D30<20,"偏贵",IF(D30>200,"偏便宜","合理")) -> 合理
A31: 棉花农场 | B31: =工厂类型!D5 -> 30000 | C31: =E18 -> 7520000 | D31: =INT(C31/B31) -> 250 | E31: =IF(D31<20,"偏贵",IF(D31>200,"偏便宜","合理")) -> 偏便宜
A32: 纺织厂 | B32: =工厂类型!D6 -> 60000 | C32: =E18 -> 7520000 | D32: =INT(C32/B32) -> 125 | E32: =IF(D32<20,"偏贵",IF(D32>200,"偏便宜","合理")) -> 合理
A33: 服装厂 | B33: =工厂类型!D7 -> 50000 | C33: =E18 -> 7520000 | D33: =INT(C33/B33) -> 150 | E33: =IF(D33<20,"偏贵",IF(D33>200,"偏便宜","合理")) -> 合理
A34: 麦田 | B34: =工厂类型!D8 -> 40000 | C34: =E18 -> 7520000 | D34: =INT(C34/B34) -> 188 | E34: =IF(D34<20,"偏贵",IF(D34>200,"偏便宜","合理")) -> 合理
A35: 面粉厂 | B35: =工厂类型!D9 -> 40000 | C35: =E18 -> 7520000 | D35: =INT(C35/B35) -> 188 | E35: =IF(D35<20,"偏贵",IF(D35>200,"偏便宜","合理")) -> 合理
A36: 食品厂 | B36: =工厂类型!D10 -> 45000 | C36: =E18 -> 7520000 | D36: =INT(C36/B36) -> 167 | E36: =IF(D36<20,"偏贵",IF(D36>200,"偏便宜","合理")) -> 合理
